Workbook

Sheet C1_Transverse
B2: WEAK STOREY CHECK FOR SEISMIC LOAD (LONGITUDINAL DIRECTION):
B3: 240C1MCS
B5: Steel Yield Strength, Fy | C5: = | D5: 350 | E5: MPa
C6: A | D6: B | E6: Total Storey Shear (kN) | F6: Comments
B7: EL 632.100
B8: Column Size | C8: W250x49 | D8: W250x49
B9: Zx = Plastic Moment of Inertia (mm^3) | C9: =VLOOKUP(C8,'W Sections'!$B$4:$U$284,20,FALSE)*10^3 -> 633000 | D9: =VLOOKUP(D8,'W Sections'!$B$4:$U$284,20,FALSE)*10^3 -> 633000
B10: Mc = FyZx (kN-m) | C10: =C9*$D$5/1000^2 -> 221.55 | D10: =D9*$D$5/1000^2 -> 221.55 | T10: M @ Top [EL 138'-4"]
B11: Number of Columns at Joint | C11: 2 | D11: 2 | U11: Mb,top / 2 = | V11: =C15/2 -> 89.775 | W11: =D15/2 -> 89.775 | X11: kN.m
B12: Beam Size | C12: W250x39 | D12: W250x39
B13: Number of Beam at Joint | C13: 1 | D13: 1 | T13: M @ Bot [EL 123'-9"]
B14: Plastic Moment of Inertia (mm^3) | C14: =VLOOKUP(C12,'W Sections'!$B$4:$U$284,20,FALSE)*10^3 -> 513000 | D14: =VLOOKUP(D12,'W Sections'!$B$4:$U$284,20,FALSE)*10^3 -> 513000 | U14: Mb,bot / 2 = | V14: 0 | W14: 0 | X14: kN.m
B15: Mb = FyZx (kN-m) | C15: =C14*$D$5/1000^2 -> 179.55 | D15: =D14*$D$5/1000^2 -> 179.55
B16: Joint Type | C16: =IF(C11*C10>C15*C13,"Strong Column - Weak Beam", "Strong Beam - Weak Column") -> Strong Column - Weak Beam | D16: =IF(D11*D10>D15*D13,"Strong Column - Weak Beam", "Strong Beam - Weak Column") -> Strong Column - Weak Beam | U16: V = [Mtop + Mbot] / h = | V16: =(V11+V14)/C20 -> 173.31081 | W16: =(W11+W14)/D20 -> 173.31081 | X16: kN
B17: Moment at the Base Mf (kN-m) | C17: 0 | D17: 0
B18: Depth of Beam(m) | C18: =VLOOKUP(C12,'W Sections'!$B$4:$U$284,6,FALSE)/1000 -> 0.262 | D18: =VLOOKUP(D12,'W Sections'!$B$4:$U$284,6,FALSE)/1000 -> 0.262 | U18: Story Shear = | V18: =V16+W16 -> 346.62162 | W18: kN
B19: Storey Height (m) | C19: 0.78 | D19: 0.78 | F19: Average Height was considered
B20: Clear Height, h (m) | C20: =C19-C18 -> 0.518 | D20: =D19-D18 -> 0.518
B21: Storey Shear (kN) | C21: =IF(C16="Strong Column - Weak Beam",(C13*C15+C17)/C20,(C10+C17)/C20) -> 346.62162 | D21: =IF(D16="Strong Column - Weak Beam",(D13*D15+D17)/D20,(D10+D17)/D20) -> 346.62162 | E21: =SUM(C21:D21) -> 693.24324
B22: EL 632.760
B23: Column Size | C23: W250x49 | D23: W250x49
B24: Zx = Plastic Moment of Inertia (mm^3) | C24: =VLOOKUP(C23,'W Sections'!$B$4:$U$284,20,FALSE)*10^3 -> 633000 | D24: =VLOOKUP(D23,'W Sections'!$B$4:$U$284,20,FALSE)*10^3 -> 633000
B25: Mc = FyZx (kN-m) | C25: =C24*$D$5/1000^2 -> 221.55 | D25: =D24*$D$5/1000^2 -> 221.55 | T25: M @ Top [EL 138'-4"]
B26: Number of Columns at Joint | C26: 2 | D26: 2 | U26: Mb,top / 2 = | V26: =C30/2 -> 89.775 | W26: =D30/2 -> 89.775 | X26: kN.m
B27: Beam Size | C27: W250x39 | D27: W250x39
B28: Number of Beam at Joint | C28: 1 | D28: 1 | T28: M @ Bot [EL 123'-9"]
B29: Plastic Moment of Inertia (mm^3) | C29: =VLOOKUP(C27,'W Sections'!$B$4:$U$284,20,FALSE)*10^3 -> 513000 | D29: =VLOOKUP(D27,'W Sections'!$B$4:$U$284,20,FALSE)*10^3 -> 513000 | U29: Mb,bot / 2 = | V29: =C15/2 -> 89.775 | W29: =D15/2 -> 89.775 | X29: kN.m
B30: Mb = FyZx (kN-m) | C30: =C29*$D$5/1000^2 -> 179.55 | D30: =D29*$D$5/1000^2 -> 179.55
B31: Joint Type | C31: =IF(C26*C25>C30*C28,"Strong Column - Weak Beam", "Strong Beam - Weak Column") -> Strong Column - Weak Beam | D31: =IF(D26*D25>D30*D28,"Strong Column - Weak Beam", "Strong Beam - Weak Column") -> Strong Column - Weak Beam | U31: V = [Mtop + Mbot] / h = | V31: =(V26+V29)/C35 -> 202.19595 | W31: =(W26+W29)/D35 -> 202.19595 | X31: kN
B32: Moment at the Base Mf (kN-m) | C32: 0 | D32: 0
B33: Depth of Beam(m) | C33: =VLOOKUP(C27,'W Sections'!$B$4:$U$284,6,FALSE)/1000 -> 0.262 | D33: =VLOOKUP(D27,'W Sections'!$B$4:$U$284,6,FALSE)/1000 -> 0.262 | U33: Story Shear = | V33: =V31+W31 -> 404.39189 | W33: kN
B34: Storey Height (m) | C34: 1.15 | D34: 1.15 | F34: Average Height was considered
B35: Clear Height, h (m) | C35: =C34-C33 -> 0.888 | D35: =D34-D33 -> 0.888
B36: Storey Shear (kN) | C36: =IF(C31="Strong Column - Weak Beam",(C28*C30+C32)/C35,(C25+C32)/C35) -> 202.19595 | D36: =IF(D31="Strong Column - Weak Beam",(D28*D30+D32)/D35,(D25+D32)/D35) -> 202.19595 | E36: =SUM(C36:D36) -> 404.39189
B37: EL 634.400
B38: Column Size | C38: W250x49 | D38: W250x49
B39: Zx = Plastic Moment of Inertia (mm^3) | C39: =VLOOKUP(C38,'W Sections'!$B$4:$U$284,20,FALSE)*10^3 -> 633000 | D39: =VLOOKUP(D38,'W Sections'!$B$4:$U$284,20,FALSE)*10^3 -> 633000
B40: Mc = FyZx (kN-m) | C40: =C39*$D$5/1000^2 -> 221.55 | D40: =D39*$D$5/1000^2 -> 221.55
B41: Number of Columns at Joint | C41: 2 | D41: 2
B42: Beam Size | C42: W250x39 | D42: W250x39
...

Sheet C1_Longitudinal
B2: WEAK STOREY CHECK FOR SEISMIC LOAD (TRANSVERSE DIRECTION):
B3: 240C1MCS
B5: Steel Yield Strength, Fy | C5: = | D5: 345 | E5: Mpa | F5: Modulus of Elasticity, E | G5: = | H5: 200000 | I5: MPa | K5: n = | L5: 1.34
B6: EL | C6: Bracing Size | D6: Bracing Length (m) | E6: Gross Area (mm^2) | F6: min. Radius of Gyration (mm) | G6: Slenderness Ratio | H6: Fe (MPa) | I6: λ | J6: Bracing Compression Capacity (kN)* | K6: Angle (degree) | L6: Horizontal Component (kN) | M6: Bracing Tension Capacity (kN) | N6: Horizontal Component (kN) | O6: Number of Compression Bracing | P6: Number of Tension Bracing | Q6: Storey Shear Strength (kN)
B7: 634.4 | C7: 2L102x76x13 | D7: 3.397 | E7: =VLOOKUP(C7,'2L'!$B$4:$Y$284,14,FALSE) -> 4200 | F7: =MIN(VLOOKUP(C7,'2L'!$B$4:$T$284,17,FALSE),VLOOKUP(C7,'2L'!$B$4:$X$284,21,FALSE)) -> 21.9 | G7: =1*D7*1000/F7 -> 155.11416 | H7: =3.14^2*$H$5/G7^2 -> 81.957071 | I7: =SQRT($D$5/H7) -> 2.0517117 | J7: 514 | K7: 42.614 | L7: =J7*COS(K7*3.14/180) -> 378.40007 | M7: =0.9*$D$5*E7/1000 -> 1304.1 | N7: =M7*COS(K7*3.14/180) -> 960.06134 | O7: 1 | P7: 0 | Q7: =L7*O7+N7*P7 -> 378.40007
B8: 637.05 | C8: 2L102x76x9.5 | D8: 3.643 | E8: =VLOOKUP(C8,'2L'!$B$4:$Y$284,14,FALSE) -> 3210 | F8: =MIN(VLOOKUP(C8,'2L'!$B$4:$T$284,17,FALSE),VLOOKUP(C8,'2L'!$B$4:$X$284,21,FALSE)) -> 22.3 | G8: =1*D8*1000/F8 -> 163.36323 | H8: =3.14^2*$H$5/G8^2 -> 73.889151 | I8: =SQRT($D$5/H8) -> 2.1608231 | J8: 360.98 | K8: 46.668 | L8: =J8*COS(K8*3.14/180) -> 247.8218 | M8: =0.9*$D$5*E8/1000 -> 996.705 | N8: =M8*COS(K8*3.14/180) -> 684.26291 | O8: 1 | P8: 0 | Q8: =L8*O8+N8*P8 -> 247.8218
B9: 639.35 | C9: 2L76x76x9.5 | D9: 3.397 | E9: =VLOOKUP(C9,'2L'!$B$4:$Y$284,14,FALSE) -> 2720 | F9: =MIN(VLOOKUP(C9,'2L'!$B$4:$T$284,17,FALSE),VLOOKUP(C9,'2L'!$B$4:$X$284,21,FALSE)) -> 23.2 | G9: =1*D9*1000/F9 -> 146.42241 | H9: =3.14^2*$H$5/G9^2 -> 91.975926 | I9: =SQRT($D$5/H9) -> 1.9367451 | J9: 202.536 | K9: 42.614 | L9: =J9*COS(K9*3.14/180) -> 149.10435 | M9: =0.9*$D$5*E9/1000 -> 844.56 | N9: =M9*COS(K9*3.14/180) -> 621.75401 | O9: 1 | P9: 0 | Q9: =L9*O9+N9*P9 -> 149.10435
B10: 640.75 | C10: 2L76x51x6.4 | D10: 2.806 | E10: =VLOOKUP(C10,'2L'!$B$4:$Y$284,14,FALSE) -> 1530 | F10: =MIN(VLOOKUP(C10,'2L'!$B$4:$T$284,17,FALSE),VLOOKUP(C10,'2L'!$B$4:$X$284,21,FALSE)) -> 14.6 | G10: =1*D10*1000/F10 -> 192.19178 | H10: =3.14^2*$H$5/G10^2 -> 53.385052 | I10: =SQRT($D$5/H10) -> 2.5421415 | J10: 168 | K10: 27.02 | L10: =J10*COS(K10*3.14/180) -> 149.68071 | M10: =0.9*$D$5*E10/1000 -> 475.065 | N10: =M10*COS(K10*3.14/180) -> 423.26229 | O10: 1 | P10: 0 | Q10: =L10*O10+N10*P10 -> 149.68071
O11: =IF(Q7<Q8,"Weak Storey",IF(Q8<Q9, "Weak Storey",IF(Q9<Q10," Weak Storey","Weak Storey Not Exist"))) -> Weak Storey
B12: *Bracing compression capacity is taken from Double-Angle Struts Compression Capacity Tables in CISC Handbook of Steel Construction. Values are interpolated for brace length.
B13: *Compression values are based on 345 MPa as per CISC design tables. Actual values will be lower as 300 MPa is spec'd, but only relative strength difference matters in this check
M17: The top elevations are nearly identical in weak story strength. The minor deviation of +/- 1 kN is acceptable by engineering judgement. OK.

Sheet D1_Transverse
B2: WEAK STOREY CHECK FOR SEISMIC LOAD (LONGITUDINAL DIRECTION):
B3: 240D1MCS
B5: Steel Yield Strength, Fy | C5: = | D5: 350 | E5: MPa
C6: A | D6: B | E6: Total Storey Shear (kN) | F6: Comments
B7: EL 633.065
B8: Column Size | C8: W250x58 | D8: W250x58
B9: Zx = Plastic Moment of Inertia (mm^3) | C9: =VLOOKUP(C8,'W Sections'!$B$4:$U$284,20,FALSE)*10^3 -> 770000 | D9: =VLOOKUP(D8,'W Sections'!$B$4:$U$284,20,FALSE)*10^3 -> 770000
B10: Mc = FyZx (kN-m) | C10: =C9*$D$5/1000^2 -> 269.5 | D10: =D9*$D$5/1000^2 -> 269.5 | T10: M @ Top [EL 138'-4"]
B11: Number of Columns at Joint | C11: 2 | D11: 2 | U11: Mb,top / 2 = | V11: =C15/2 -> 89.775 | W11: =D15/2 -> 89.775 | X11: kN.m
B12: Beam Size | C12: W250x39 | D12: W250x39
B13: Number of Beam at Joint | C13: 1 | D13: 1 | T13: M @ Bot [EL 123'-9"]
B14: Plastic Moment of Inertia (mm^3) | C14: =VLOOKUP(C12,'W Sections'!$B$4:$U$284,20,FALSE)*10^3 -> 513000 | D14: =VLOOKUP(D12,'W Sections'!$B$4:$U$284,20,FALSE)*10^3 -> 513000 | U14: Mb,bot / 2 = | V14: 0 | W14: 0 | X14: kN.m
B15: Mb = FyZx (kN-m) | C15: =C14*$D$5/1000^2 -> 179.55 | D15: =D14*$D$5/1000^2 -> 179.55
B16: Joint Type | C16: =IF(C11*C10>C15*C13,"Strong Column - Weak Beam", "Strong Beam - Weak Column") -> Strong Column - Weak Beam | D16: =IF(D11*D10>D15*D13,"Strong Column - Weak Beam", "Strong Beam - Weak Column") -> Strong Column - Weak Beam | U16: V = [Mtop + Mbot] / h = | V16: =(V11+V14)/C20 -> 47.362174 | W16: =(W11+W14)/D20 -> 47.362174 | X16: kN
B17: Moment at the Base Mf (kN-m) | C17: 0 | D17: 0
B18: Depth of Beam(m) | C18: =VLOOKUP(C12,'W Sections'!$B$4:$U$284,6,FALSE)/1000 -> 0.262 | D18: =VLOOKUP(D12,'W Sections'!$B$4:$U$284,6,FALSE)/1000 -> 0.262 | U18: Story Shear = | V18: =V16+W16 -> 94.724347 | W18: kN
B19: Storey Height (m) | C19: 2.1575 | D19: 2.1575 | F19: Average Height was considered
B20: Clear Height, h (m) | C20: =C19-C18 -> 1.8955 | D20: =D19-D18 -> 1.8955
B21: Storey Shear (kN) | C21: =IF(C16="Strong Column - Weak Beam",(C13*C15+C17)/C20,(C10+C17)/C20) -> 94.724347 | D21: =IF(D16="Strong Column - Weak Beam",(D13*D15+D17)/D20,(D10+D17)/D20) -> 94.724347 | E21: =SUM(C21:D21) -> 189.44869
B22: EL 634.750
B23: Column Size | C23: W250x58 | D23: W250x58
B24: Zx = Plastic Moment of Inertia (mm^3) | C24: =VLOOKUP(C23,'W Sections'!$B$4:$U$284,20,FALSE)*10^3 -> 770000 | D24: =VLOOKUP(D23,'W Sections'!$B$4:$U$284,20,FALSE)*10^3 -> 770000
B25: Mc = FyZx (kN-m) | C25: =C24*$D$5/1000^2 -> 269.5 | D25: =D24*$D$5/1000^2 -> 269.5 | T25: M @ Top [EL 138'-4"]
B26: Number of Columns at Joint | C26: 2 | D26: 2 | U26: Mb,top / 2 = | V26: =C30/2 -> 89.775 | W26: =D30/2 -> 89.775 | X26: kN.m
B27: Beam Size | C27: W250x39 | D27: W250x39
B28: Number of Beam at Joint | C28: 1 | D28: 1 | T28: M @ Bot [EL 123'-9"]
B29: Plastic Moment of Inertia (mm^3) | C29: =VLOOKUP(C27,'W Sections'!$B$4:$U$284,20,FALSE)*10^3 -> 513000 | D29: =VLOOKUP(D27,'W Sections'!$B$4:$U$284,20,FALSE)*10^3 -> 513000 | U29: Mb,bot / 2 = | V29: =C15/2 -> 89.775 | W29: =D15/2 -> 89.775 | X29: kN.m
B30: Mb = FyZx (kN-m) | C30: =C29*$D$5/1000^2 -> 179.55 | D30: =D29*$D$5/1000^2 -> 179.55
B31: Joint Type | C31: =IF(C26*C25>C30*C28,"Strong Column - Weak Beam", "Strong Beam - Weak Column") -> Strong Column - Weak Beam | D31: =IF(D26*D25>D30*D28,"Strong Column - Weak Beam", "Strong Beam - Weak Column") -> Strong Column - Weak Beam | U31: V = [Mtop + Mbot] / h = | V31: =(V26+V29)/C35 -> 73.121564 | W31: =(W26+W29)/D35 -> 73.121564 | X31: kN
B32: Moment at the Base Mf (kN-m) | C32: 0 | D32: 0
B33: Depth of Beam(m) | C33: =VLOOKUP(C27,'W Sections'!$B$4:$U$284,6,FALSE)/1000 -> 0.262 | D33: =VLOOKUP(D27,'W Sections'!$B$4:$U$284,6,FALSE)/1000 -> 0.262 | U33: Story Shear = | V33: =V31+W31 -> 146.24313 | W33: kN
B34: Storey Height (m) | C34: =5.435/2 -> 2.7175 | D34: =5.435/2 -> 2.7175 | F34: Average Height was considered
B35: Clear Height, h (m) | C35: =C34-C33 -> 2.4555 | D35: =D34-D33 -> 2.4555
B36: Storey Shear (kN) | C36: =IF(C31="Strong Column - Weak Beam",(C28*C30+C32)/C35,(C25+C32)/C35) -> 73.121564 | D36: =IF(D31="Strong Column - Weak Beam",(D28*D30+D32)/D35,(D25+D32)/D35) -> 73.121564 | E36: =SUM(C36:D36) -> 146.24313
B37: EL 638.500
B38: Column Size | C38: W250x58 | D38: W250x58
B39: Zx = Plastic Moment of Inertia (mm^3) | C39: =VLOOKUP(C38,'W Sections'!$B$4:$U$284,20,FALSE)*10^3 -> 770000 | D39: =VLOOKUP(D38,'W Sections'!$B$4:$U$284,20,FALSE)*10^3 -> 770000
B40: Mc = FyZx (kN-m) | C40: =C39*$D$5/1000^2 -> 269.5 | D40: =D39*$D$5/1000^2 -> 269.5 | T40: M @ Top [EL 138'-4"]
B41: Number of Columns at Joint | C41: 2 | D41: 2 | U41: Mb,top / 2 = | V41: =C45/2 -> 89.775 | W41: =D45/2 -> 89.775 | X41: kN.m
B42: Beam Size | C42: W250x39 | D42: W250x39
...

Sheet D1_Longitudinal
B2: WEAK STOREY CHECK FOR SEISMIC LOAD (TRANSVERSE DIRECTION):
B3: 240C1MCS
B5: Steel Yield Strength, Fy | C5: = | D5: 345 | E5: Mpa | F5: Modulus of Elasticity, E | G5: = | H5: 200000 | I5: MPa | K5: n = | L5: 1.34
B6: EL | C6: Bracing Size | D6: Bracing Length (m) | E6: Gross Area (mm^2) | F6: min. Radius of Gyration (mm) | G6: Slenderness Ratio | H6: Fe (Mpa) | I6: λ | J6: Bracing Compression Capacity (kN)* | K6: Angle (degree) | L6: Horizontal Component (kN) | M6: Bracing Tension Capacity (kN) | N6: Horizontal Component (kN) | O6: Number of Compression Bracing | P6: Number of Tension Bracing | Q6: Storey Shear Strength (kN)
B7: 634.55 | C7: 2L102x76x13 | D7: 2.696 | E7: =VLOOKUP(C7,'2L'!$B$4:$Y$284,14,FALSE) -> 4200 | F7: =MIN(VLOOKUP(C7,'2L'!$B$4:$T$284,17,FALSE),VLOOKUP(C7,'2L'!$B$4:$X$284,21,FALSE)) -> 21.9 | G7: =1*D7*1000/F7 -> 123.10502 | H7: =3.14^2*$H$5/G7^2 -> 130.11811 | I7: =SQRT($D$5/H7) -> 1.6283234 | J7: 695 | K7: 56.192 | L7: =J7*COS(K7*3.14/180) -> 386.99316 | M7: =0.9*$D$5*E7/1000 -> 1304.1 | N7: =M7*COS(K7*3.14/180) -> 726.15508 | O7: 1 | P7: 1 | Q7: =L7*O7+N7*P7 -> 1113.1482
B8: 636.45 | C8: 2L76x76x9.5 | D8: 2.421 | E8: =VLOOKUP(C8,'2L'!$B$4:$Y$284,14,FALSE) -> 2720 | F8: =MIN(VLOOKUP(C8,'2L'!$B$4:$T$284,17,FALSE),VLOOKUP(C8,'2L'!$B$4:$X$284,21,FALSE)) -> 23.2 | G8: =1*D8*1000/F8 -> 104.35345 | H8: =3.14^2*$H$5/G8^2 -> 181.08217 | I8: =SQRT($D$5/H8) -> 1.3802943 | J8: 344.696 | K8: 51.71 | L8: =J8*COS(K8*3.14/180) -> 213.7119 | M8: =0.9*$D$5*E8/1000 -> 844.56 | N8: =M8*COS(K8*3.14/180) -> 523.62813 | O8: 1 | P8: 1 | Q8: =L8*O8+N8*P8 -> 737.34003
B9: 638.5 | C9: 2L76x76x9.5 | D9: 2.54 | E9: =VLOOKUP(C9,'2L'!$B$4:$Y$284,14,FALSE) -> 2720 | F9: =MIN(VLOOKUP(C9,'2L'!$B$4:$T$284,17,FALSE),VLOOKUP(C9,'2L'!$B$4:$X$284,21,FALSE)) -> 23.2 | G9: =1*D9*1000/F9 -> 109.48276 | H9: =3.14^2*$H$5/G9^2 -> 164.51209 | I9: =SQRT($D$5/H9) -> 1.4481403 | J9: 320.6 | K9: 53.807 | L9: =J9*COS(K9*3.14/180) -> 189.43973 | M9: =0.9*$D$5*E9/1000 -> 844.56 | N9: =M9*COS(K9*3.14/180) -> 499.04309 | O9: 1 | P9: 1 | Q9: =L9*O9+N9*P9 -> 688.48282
B10: 640.4 | C10: 2L76x51x6.4 | D10: 2.324 | E10: =VLOOKUP(C10,'2L'!$B$4:$Y$284,14,FALSE) -> 1530 | F10: =MIN(VLOOKUP(C10,'2L'!$B$4:$T$284,17,FALSE),VLOOKUP(C10,'2L'!$B$4:$X$284,21,FALSE)) -> 14.6 | G10: =1*D10*1000/F10 -> 159.17808 | H10: =3.14^2*$H$5/G10^2 -> 77.82565 | I10: =SQRT($D$5/H10) -> 2.1054657 | J10: 219.5 | K10: 49.8 | L10: =J10*COS(K10*3.14/180) -> 141.75182 | M10: =0.9*$D$5*E10/1000 -> 475.065 | N10: =M10*COS(K10*3.14/180) -> 306.79421 | O10: 1 | P10: 1 | Q10: =L10*O10+N10*P10 -> 448.54603
O11: =IF(Q7<Q8,"Weak Storey",IF(Q8<Q9, "Weak Storey",IF(Q9<Q10," Weak Storey","Weak Storey Not Exist"))) -> Weak Storey Not Exist
B12: *Bracing compression capacity is taken from Double-Angle Struts Compression Capacity Tables in CISC Handbook of Steel Construction. Values are interpolated for brace length.
B13: *Compression values are based on 345 MPa as per CISC design tables. Actual values will be lower as 300 MPa is spec'd, but only relative strength difference matters in this check

Sheet W Sections
A1: Prp | B1: Dsg | C1: Avl | D1: Shp | E1: Grp | F1: Use | G1: D | H1: B | I1: T | J1: W | K1: BT | L1: HW | M1: K | N1: K1 | O1: Dnom | P1: Mass | Q1: A | R1: Ix | S1: Sx | T1: Rx | U1: Zx | V1: Iy | W1: Sy | X1: Ry | Y1: Zy | Z1: J | AA1: Cw | AB1: Wn | AC1: Sw | AD1: Qf | AE1: Qw | AF1: SA | AG1: Ds_i | AH1: Dn_i | AI1: Wt_i
R2: 10^6 | S2: 10^3 | U2: 10^3 | V2: 10^6 | W2: 10^3 | Y2: 10^3 | Z2: 10^3 | AA2: 10^9 | AC2: 10^6 | AD2: 10^3 | AE2: 10^3
A3: W: Wide-Flange Shapes | G3: mm | H3: mm | I3: mm | J3: mm | M3: mm | N3: mm | O3: mm | P3: kg/m | Q3: mm^2 | R3: mm^4 | S3: mm^3 | T3: mm | U3: mm^3 | V3: mm^4 | W3: mm^3 | X3: mm | Y3: mm^3 | Z3: mm^4 | AA3: mm^6 | AB3: mm^2 | AC3: mm^4 | AD3: mm^3 | AE3: mm^3 | AF3: m | AH3: in | AI3: lb/ft
A4: * | B4: W1100x499 | C4: * | D4: 1 | F4: 3 | G4: 1118 | H4: 405 | I4: 45 | J4: 25.9 | K4: 4.5 | L4: 39.7 | M4: 67 | N4: 33 | O4: 1100 | P4: 499 | Q4: 63400 | R4: 12900 | S4: 23100 | T4: 452 | U4: 26600 | V4: 500 | W4: 2470 | X4: 88.8 | Y4: 3870 | Z4: 31000 | AA4: 144000 | AB4: 109000 | AC4: 495 | AD4: 4580 | AE4: 13200 | AF4: 3.8 | AG4: W44x335 | AH4: 44 | AI4: 335
B5: W1100x433 | C5: * | D5: 1 | F5: 3 | G5: 1108 | H5: 402 | I5: 40.1 | J5: 22.1 | K5: 5.01 | L5: 46.5 | M5: 62 | N5: 31 | O5: 1100 | P5: 433 | Q5: 55300 | R5: 11300 | S5: 20400 | T5: 452 | U5: 23200 | V5: 435 | W5: 2170 | X5: 88.7 | Y5: 3370 | Z5: 21400 | AA5: 124000 | AB5: 107000 | AC5: 433 | AD5: 4070 | AE5: 11500 | AF5: 3.78 | AG5: W44x290 | AH5: 44 | AI5: 290
B6: W1100x390 | C6: * | D6: 1 | F6: 3 | G6: 1100 | H6: 400 | I6: 36.1 | J6: 20.1 | K6: 5.54 | L6: 51.1 | M6: 58 | N6: 30 | O6: 1100 | P6: 390 | Q6: 49900 | R6: 10100 | S6: 18300 | T6: 450 | U6: 20800 | V6: 386 | W6: 1930 | X6: 87.9 | Y6: 3000 | Z6: 15700 | AA6: 109000 | AB6: 106000 | AC6: 384 | AD6: 3650 | AE6: 10300 | AF6: 3.76 | AG6: W44x262 | AH6: 44 | AI6: 262
B7: W1100x343 | C7: * | D7: 1 | F7: 3 | G7: 1090 | H7: 400 | I7: 31 | J7: 18 | K7: 6.45 | L7: 57.1 | M7: 53 | N7: 29 | O7: 1100 | P7: 343 | Q7: 43600 | R7: 8670 | S7: 15900 | T7: 446 | U7: 18100 | V7: 331 | W7: 1660 | X7: 87.1 | Y7: 2570 | Z7: 10300 | AA7: 92900 | AB7: 106000 | AC7: 328 | AD7: 3140 | AE7: 8940 | AF7: 3.74 | AG7: W44x230 | AH7: 44 | AI7: 230
A8: * | B8: W1000x883 | C8: * | D8: 1 | F8: 3 | G8: 1092 | H8: 424 | I8: 82 | J8: 45.5 | K8: 2.59 | L8: 20.4 | M8: 114 | N8: 53 | O8: 1000 | P8: 883 | Q8: 113000 | R8: 21000 | S8: 38400 | T8: 432 | U8: 45300 | V8: 1050 | W8: 4950 | X8: 96.6 | Y8: 7870 | Z8: 185000 | AA8: 268000 | AB8: 107000 | AC8: 931 | AD8: 7840 | AE8: 22500 | AF8: 3.79 | AG8: W40x593 | AH8: 40 | AI8: 593
B9: W1000x748 | C9: * | D9: 1 | F9: 3 | G9: 1068 | H9: 417 | I9: 70.1 | J9: 39.1 | K9: 2.97 | L9: 23.7 | M9: 102 | N9: 50 | O9: 1000 | P9: 748 | Q9: 95500 | R9: 17300 | S9: 32500 | T9: 426 | U9: 37900 | V9: 852 | W9: 4090 | X9: 94.5 | Y9: 6470 | Z9: 116000 | AA9: 212000 | AB9: 104000 | AC9: 760 | AD9: 6610 | AE9: 18800 | AF9: 3.73 | AG9: W40x503 | AH9: 40 | AI9: 503
B10: W1000x642 | C10: * | D10: 1 | F10: 3 | G10: 1048 | H10: 412 | I10: 59.9 | J10: 34 | K10: 3.44 | L10: 27.3 | M10: 91 | N10: 47 | O10: 1000 | P10: 642 | Q10: 81700 | R10: 14500 | S10: 27700 | T10: 421 | U10: 32100 | V10: 702 | W10: 3410 | X10: 92.7 | Y10: 5370 | Z10: 73500 | AA10: 171000 | AB10: 102000 | AC10: 628 | AD10: 5590 | AE10: 15900 | AF10: 3.68 | AG10: W40x431 | AH10: 40 | AI10: 431
B11: W1000x591 | C11: * | D11: 1 | F11: 3 | G11: 1040 | H11: 409 | I11: 55.9 | J11: 31 | K11: 3.66 | L11: 29.9 | M11: 87 | N11: 46 | O11: 1000 | P11: 591 | Q11: 75300 | R11: 13300 | S11: 25600 | T11: 421 | U11: 29500 | V11: 640 | W11: 3130 | X11: 92.2 | Y11: 4920 | Z11: 59000 | AA11: 155000 | AB11: 101000 | AC11: 575 | AD11: 5200 | AE11: 14600 | AF11: 3.65 | AG11: W40x397 | AH11: 40 | AI11: 397
B12: W1000x554 | C12: * | D12: 1 | F12: 3 | G12: 1032 | H12: 408 | I12: 52.1 | J12: 29.5 | K12: 3.92 | L12: 31.5 | M12: 84 | N12: 45 | O12: 1000 | P12: 554 | Q12: 70700 | R12: 12300 | S12: 23900 | T12: 418 | U12: 27500 | V12: 592 | W12: 2900 | X12: 91.5 | Y12: 4550 | Z12: 48600 | AA12: 142000 | AB12: 99900 | AC12: 531 | AD12: 4830 | AE12: 13600 | AF12: 3.64 | AG12: W40x372 | AH12: 40 | AI12: 372
B13: W1000x539 | C13: * | D13: 1 | F13: 3 | G13: 1030 | H13: 407 | I13: 51.1 | J13: 28.4 | K13: 3.98 | L13: 32.7 | M13: 83 | N13: 44 | O13: 1000 | P13: 539 | Q13: 68700 | R13: 12000 | S13: 23400 | T13: 418 | U13: 26800 | V13: 576 | W13: 2830 | X13: 91.6 | Y13: 4440 | Z13: 45300 | AA13: 138000 | AB13: 99600 | AC13: 518 | AD13: 4730 | AE13: 13200 | AF13: 3.63 | AG13: W40x362 | AH13: 40 | AI13: 362
B14: W1000x483 | C14: * | D14: 1 | F14: 3 | G14: 1020 | H14: 404 | I14: 46 | J14: 25.4 | K14: 4.39 | L14: 36.5 | M14: 78 | N14: 43 | O14: 1000 | P14: 483 | Q14: 61500 | R14: 10700 | S14: 20900 | T14: 417 | U14: 23900 | V14: 507 | W14: 2510 | X14: 90.8 | Y14: 3920 | Z14: 33100 | AA14: 120000 | AB14: 98400 | AC14: 457 | AD14: 4240 | AE14: 11800 | AF14: 3.61 | AG14: W40x324 | AH14: 40 | AI14: 324
B15: W1000x443 | C15: * | D15: 1 | F15: 3 | G15: 1012 | H15: 402 | I15: 41.9 | J15: 23.6 | K15: 4.8 | L15: 39.3 | M15: 73 | N15: 42 | O15: 1000 | P15: 443 | Q15: 56400 | R15: 9670 | S15: 19100 | T15: 414 | U15: 21800 | V15: 455 | W15: 2260 | X15: 89.8 | Y15: 3530 | Z15: 25400 | AA15: 107000 | AB15: 97500 | AC15: 411 | AD15: 3850 | AE15: 10700 | AF15: 3.58 | AG15: W40x297 | AH15: 40 | AI15: 297
B16: W1000x412 | C16: * | D16: 1 | F16: 3 | G16: 1008 | H16: 402 | I16: 40 | J16: 21.1 | K16: 5.03 | L16: 44 | M16: 72 | N16: 41 | O16: 1000 | P16: 412 | Q16: 52500 | R16: 9100 | S16: 18100 | T16: 416 | U16: 20500 | V16: 434 | W16: 2160 | X16: 90.9 | Y16: 3350 | Z16: 21400 | AA16: 102000 | AB16: 97300 | AC16: 391 | AD16: 3690 | AE16: 10100 | AF16: 3.58 | AG16: W40x277 | AH16: 40 | AI16: 277
B17: W1000x371 | C17: * | D17: 1 | F17: 3 | G17: 1000 | H17: 400 | I17: 36.1 | J17: 19 | K17: 5.54 | L17: 48.8 | M17: 68 | N17: 40 | O17: 1000 | P17: 371 | Q17: 47300 | R17: 8140 | S17: 16300 | T17: 415 | U17: 18400 | V17: 386 | W17: 1930 | X17: 90.3 | Y17: 2980 | Z17: 15900 | AA17: 89600 | AB17: 96400 | AC17: 348 | AD17: 3310 | AE17: 9000 | AF17: 3.56 | AG17: W40x249 | AH17: 40 | AI17: 249
B18: W1000x321 | C18: * | D18: 1 | F18: 3 | G18: 990 | H18: 400 | I18: 31 | J18: 16.5 | K18: 6.45 | L18: 56.2 | M18: 63 | N18: 38 | O18: 1000 | P18: 321 | Q18: 40900 | R18: 6960 | S18: 14100 | T18: 413 | U18: 15800 | V18: 331 | W18: 1660 | X18: 90 | Y18: 2550 | Z18: 10300 | AA18: 76100 | AB18: 95900 | AC18: 297 | AD18: 2850 | AE18: 7720 | AF18: 3.55 | AG18: W40x215 | AH18: 40 | AI18: 215
B19: W1000x296 | C19: * | D19: 1 | F19: 3 | G19: 982 | H19: 400 | I19: 27.1 | J19: 16.5 | K19: 7.38 | L19: 56.2 | M19: 59 | N19: 38 | O19: 1000 | P19: 296 | Q19: 37800 | R19: 6200 | S19: 12600 | T19: 405 | U19: 14300 | V19: 290 | W19: 1450 | X19: 87.6 | Y19: 2240 | Z19: 7640 | AA19: 66000 | AB19: 95500 | AC19: 259 | AD19: 2480 | AE19: 6950 | AF19: 3.53 | AG19: W40x199 | AH19: 40 | AI19: 199
A20: * | B20: W1000x584 | C20: * | D20: 1 | F20: 3 | G20: 1056 | H20: 314 | I20: 64 | J20: 36.1 | K20: 2.45 | L20: 25.7 | M20: 96 | N20: 48 | O20: 1000 | P20: 584 | Q20: 74500 | R20: 12500 | S20: 23600 | T20: 409 | U20: 28100 | V20: 334 | W20: 2130 | X20: 67 | Y20: 3480 | Z20: 71700 | AA20: 82300 | AB20: 77900 | AC20: 391 | AD20: 4410 | AE20: 13900 | AF20: 3.3 | AG20: W40x392 | AH20: 40 | AI20: 392
B21: W1000x494 | C21: * | D21: 1 | F21: 3 | G21: 1036 | H21: 309 | I21: 54 | J21: 31 | K21: 2.86 | L21: 29.9 | M21: 86 | N21: 46 | O21: 1000 | P21: 494 | Q21: 62900 | R21: 10300 | S21: 19800 | T21: 404 | U21: 23400 | V21: 268 | W21: 1740 | X21: 65.3 | Y21: 2820 | Z21: 44000 | AA21: 64700 | AB21: 75900 | AC21: 316 | AD21: 3690 | AE21: 11500 | AF21: 3.25 | AG21: W40x331 | AH21: 40 | AI21: 331
B22: W1000x486 | C22: * | D22: 1 | F22: 3 | G22: 1036 | H22: 308 | I22: 54.1 | J22: 30 | K22: 2.85 | L22: 30.9 | M22: 86 | N22: 45 | O22: 1000 | P22: 486 | Q22: 61900 | R22: 10200 | S22: 19700 | T22: 406 | U22: 23200 | V22: 266 | W22: 1730 | X22: 65.5 | Y22: 2790 | Z22: 42900 | AA22: 64100 | AB22: 75600 | AC22: 315 | AD22: 3690 | AE22: 11400 | AF22: 3.24 | AG22: W40x327 | AH22: 40 | AI22: 327
B23: W1000x438 | C23: * | D23: 1 | F23: 3 | G23: 1026 | H23: 305 | I23: 49 | J23: 26.9 | K23: 3.11 | L23: 34.5 | M23: 81 | N23: 43 | O23: 1000 | P23: 438 | Q23: 55600 | R23: 9090 | S23: 17700 | T23: 404 | U23: 20700 | V23: 234 | W23: 1530 | X23: 64.8 | Y23: 2460 | Z23: 31800 | AA23: 55700 | AB23: 74500 | AC23: 278 | AD23: 3330 | AE23: 10200 | AF23: 3.22 | AG23: W40x294 | AH23: 40 | AI23: 294
B24: W1000x415 | C24: * | D24: 1 | F24: 3 | G24: 1020 | H24: 304 | I24: 46 | J24: 25.9 | K24: 3.3 | L24: 35.8 | M24: 78 | N24: 43 | O24: 1000 | P24: 415 | Q24: 52800 | R24: 8520 | S24: 16700 | T24: 402 | U24: 19500 | V24: 217 | W24: 1430 | X24: 64.1 | Y24: 2300 | Z24: 27000 | AA24: 51500 | AB24: 74000 | AC24: 259 | AD24: 3110 | AE24: 9600 | AF24: 3.2 | AG24: W40x278 | AH24: 40 | AI24: 278
B25: W1000x393 | C25: * | D25: 1 | F25: 3 | G25: 1016 | H25: 303 | I25: 43.9 | J25: 24.4 | K25: 3.45 | L25: 38 | M25: 75 | N25: 42 | O25: 1000 | P25: 393 | Q25: 50000 | R25: 8080 | S25: 15900 | T25: 402 | U25: 18500 | V25: 205 | W25: 1350 | X25: 64 | Y25: 2170 | Z25: 23300 | AA25: 48400 | AB25: 73600 | AC25: 245 | AD25: 2970 | AE25: 9090 | AF25: 3.2 | AG25: W40x264 | AH25: 40 | AI25: 264
B26: W1000x350 | C26: * | D26: 1 | F26: 3 | G26: 1008 | H26: 302 | I26: 40 | J26: 21.1 | K26: 3.78 | L26: 44 | M26: 72 | N26: 41 | O26: 1000 | P26: 350 | Q26: 44500 | R26: 7230 | S26: 14300 | T26: 403 | U26: 16600 | V26: 185 | W26: 1220 | X26: 64.4 | Y26: 1940 | Z26: 17200 | AA26: 43200 | AB26: 73100 | AC26: 221 | AD26: 2720 | AE26: 8120 | AF26: 3.18 | AG26: W40x235 | AH26: 40 | AI26: 235
B27: W1000x314 | C27: * | D27: 1 | F27: 3 | G27: 1000 | H27: 300 | I27: 35.9 | J27: 19.1 | K27: 4.18 | L27: 48.6 | M27: 67 | N27: 40 | O27: 1000 | P27: 314 | Q27: 40000 | R27: 6440 | S27: 12900 | T27: 401 | U27: 14900 | V27: 162 | W27: 1080 | X27: 63.7 | Y27: 1710 | Z27: 12600 | AA27: 37700 | AB27: 72300 | AC27: 195 | AD27: 2430 | AE27: 7250 | AF27: 3.16 | AG27: W40x211 | AH27: 40 | AI27: 211
B28: W1000x272 | C28: * | D28: 1 | F28: 3 | G28: 990 | H28: 300 | I28: 31 | J28: 16.5 | K28: 4.84 | L28: 56.2 | M28: 63 | N28: 38 | O28: 1000 | P28: 272 | Q28: 34700 | R28: 5540 | S28: 11200 | T28: 400 | U28: 12800 | V28: 140 | W28: 933 | X28: 63.5 | Y28: 1470 | Z28: 8350 | AA28: 32200 | AB28: 71900 | AC28: 167 | AD28: 2110 | AE28: 6240 | AF28: 3.15 | AG28: W40x183 | AH28: 40 | AI28: 183
B29: W1000x249 | C29: * | D29: 1 | F29: 3 | G29: 980 | H29: 300 | I29: 26 | J29: 16.5 | K29: 5.77 | L29: 56.2 | M29: 58 | N29: 38 | O29: 1000 | P29: 249 | Q29: 31700 | R29: 4810 | S29: 9820 | T29: 390 | U29: 11300 | V29: 118 | W29: 783 | X29: 60.9 | Y29: 1240 | Z29: 5820 | AA29: 26700 | AB29: 71600 | AC29: 140 | AD29: 1760 | AE29: 5500 | AF29: 3.13 | AG29: W40x167 | AH29: 40 | AI29: 167
B30: W1000x222 | C30: * | D30: 1 | F30: 3 | G30: 970 | H30: 300 | I30: 21.1 | J30: 16 | K30: 7.11 | L30: 58 | M30: 53 | N30: 38 | O30: 1000 | P30: 222 | Q30: 28300 | R30: 4080 | S30: 8410 | T30: 380 | U30: 9800 | V30: 95.4 | W30: 636 | X30: 58.1 | Y30: 1020 | Z30: 3900 | AA30: 21500 | AB30: 71200 | AC30: 113 | AD30: 1420 | AE30: 4720 | AF30: 3.11 | AG30: W40x149 | AH30: 40 | AI30: 149
A31: * | B31: W920x1191 | C31: * | D31: 1 | F31: 3 | G31: 1081 | H31: 457 | I31: 109 | J31: 60.5 | K31: 2.1 | L31: 14.3 | M31: 141 | N31: 60 | O31: 920 | P31: 1191 | Q31: 152000 | R31: 27000 | S31: 49900 | T31: 421 | U31: 59900 | V31: 1750 | W31: 7660 | X31: 107 | Y31: 12200 | Z31: 440000 | AA31: 413000 | AB31: 111000 | AC31: 1380 | AD31: 10500 | AE31: 29800 | AF31: 3.87 | AG31: W36x800 | AH31: 36 | AI31: 800
B32: W920x970 | C32: * | D32: 1 | F32: 3 | G32: 1043 | H32: 446 | I32: 89.9 | J32: 50 | K32: 2.48 | L32: 17.3 | M32: 121 | N32: 55 | O32: 920 | P32: 970 | Q32: 124000 | R32: 21000 | S32: 40300 | T32: 412 | U32: 47700 | V32: 1340 | W32: 6000 | X32: 104 | Y32: 9500 | Z32: 246000 | AA32: 304000 | AB32: 106000 | AC32: 1070 | AD32: 8480 | AE32: 23800 | AF32: 3.77 | AG32: W36x652 | AH32: 36 | AI32: 652
B33: W920x787 | C33: * | D33: 1 | F33: 3 | G33: 1011 | H33: 437 | I33: 73.9 | J33: 40.9 | K33: 2.96 | L33: 21.1 | M33: 105 | N33: 50 | O33: 920 | P33: 787 | Q33: 100000 | R33: 16500 | S33: 32600 | T33: 405 | U33: 38100 | V33: 1030 | W33: 4730 | X33: 101 | Y33: 7430 | Z33: 136000 | AA33: 227000 | AB33: 102000 | AC33: 827 | AD33: 6860 | AE33: 18900 | AF33: 3.69 | AG33: W36x529 | AH33: 36 | AI33: 529
B34: W920x725 | C34: * | D34: 1 | F34: 3 | G34: 999 | H34: 434 | I34: 68.1 | J34: 38.1 | K34: 3.19 | L34: 22.6 | M34: 100 | N34: 49 | O34: 920 | P34: 725 | Q34: 92500 | R34: 15000 | S34: 29900 | T34: 402 | U34: 34800 | V34: 932 | W34: 4300 | X34: 100 | Y34: 6740 | Z34: 107000 | AA34: 202000 | AB34: 101000 | AC34: 746 | AD34: 6270 | AE34: 17300 | AF34: 3.66 | AG34: W36x487 | AH34: 36 | AI34: 487
B35: W920x656 | C35: * | D35: 1 | F35: 3 | G35: 987 | H35: 431 | I35: 62 | J35: 34.5 | K35: 3.48 | L35: 25 | M35: 94 | N35: 47 | O35: 920 | P35: 656 | Q35: 83700 | R35: 13400 | S35: 27100 | T35: 400 | U35: 31400 | V35: 831 | W35: 3850 | X35: 99.6 | Y35: 6030 | Z35: 80700 | AA35: 178000 | AB35: 99700 | AC35: 666 | AD35: 5680 | AE35: 15600 | AF35: 3.63 | AG35: W36x441 | AH35: 36 | AI35: 441
B36: W920x588 | C36: * | D36: 1 | F36: 3 | G36: 976 | H36: 427 | I36: 55.9 | J36: 31 | K36: 3.82 | L36: 27.9 | M36: 87 | N36: 46 | O36: 920 | P36: 588 | Q36: 75000 | R36: 11900 | S36: 24300 | T36: 398 | U36: 28000 | V36: 728 | W36: 3410 | X36: 98.5 | Y36: 5310 | Z36: 59100 | AA36: 154000 | AB36: 98200 | AC36: 586 | AD36: 5090 | AE36: 13900 | AF36: 3.6 | AG36: W36x395 | AH36: 36 | AI36: 395
B37: W920x537 | C37: * | D37: 1 | F37: 3 | G37: 965 | H37: 425 | I37: 51.1 | J37: 28.4 | K37: 4.16 | L37: 30.4 | M37: 83 | N37: 44 | O37: 920 | P37: 537 | Q37: 68400 | R37: 10700 | S37: 22200 | T37: 395 | U37: 25300 | V37: 656 | W37: 3090 | X37: 97.9 | Y37: 4800 | Z37: 45300 | AA37: 137000 | AB37: 97100 | AC37: 527 | AD37: 4630 | AE37: 12600 | AF37: 3.57 | AG37: W36x361 | AH37: 36 | AI37: 361
B38: W920x491 | C38: * | D38: 1 | F38: 3 | G38: 957 | H38: 422 | I38: 47 | J38: 25.9 | K38: 4.49 | L38: 33.3 | M38: 79 | N38: 43 | O38: 920 | P38: 491 | Q38: 62500 | R38: 9700 | S38: 20300 | T38: 394 | U38: 23100 | V38: 590 | W38: 2800 | X38: 97.2 | Y38: 4340 | Z38: 35100 | AA38: 122000 | AB38: 96000 | AC38: 476 | AD38: 4240 | AE38: 11400 | AF38: 3.55 | AG38: W36x330 | AH38: 36 | AI38: 330
B39: W920x449 | C39: * | D39: 1 | F39: 3 | G39: 948 | H39: 423 | I39: 42.7 | J39: 24 | K39: 4.95 | L39: 35.9 | M39: 74 | N39: 42 | O39: 920 | P39: 449 | Q39: 57300 | R39: 8780 | S39: 18500 | T39: 391 | U39: 21000 | V39: 540 | W39: 2550 | X39: 97 | Y39: 3950 | Z39: 26800 | AA39: 111000 | AB39: 95700 | AC39: 432 | AD39: 3860 | AE39: 10400 | AF39: 3.54 | AG39: W36x302 | AH39: 36 | AI39: 302
B40: W920x420 | C40: * | D40: 1 | F40: 3 | G40: 943 | H40: 422 | I40: 39.9 | J40: 22.5 | K40: 5.29 | L40: 38.4 | M40: 71 | N40: 41 | O40: 920 | P40: 420 | Q40: 53600 | R40: 8170 | S40: 17300 | T40: 390 | U40: 19600 | V40: 501 | W40: 2370 | X40: 96.7 | Y40: 3670 | Z40: 22000 | AA40: 102000 | AB40: 95300 | AC40: 401 | AD40: 3600 | AE40: 9700 | AF40: 3.53 | AG40: W36x282 | AH40: 36 | AI40: 282
...

Sheet 2L
A1: Prp | B1: Dsg | C1: Avl | D1: Shp | E1: Grp | F1: D | G1: B | H1: T | I1: Ryp | J1: BT | K1: DT | L1: K | M1: TanA | N1: Mass | O1: A | P1: Ix | Q1: Sx | R1: Rx | S1: Y | T1: Ry0 | U1: Ry8 | V1: Ry10 | W1: Ry12 | X1: Ry16 | Y1: Ry20 | Z1: Yo | AA1: J | AB1: Cw | AC1: SA | AD1: Ds_i | AE1: Wt_i
P2: 10^6 | Q2: 10^3 | AA2: 10^3 | AB2: 10^9
A3: 2L: Double Angles | F3: mm | G3: mm | H3: mm | I3: mm | L3: mm | N3: kg/m | O3: mm^2 | P3: mm^4 | Q3: mm^3 | R3: mm | S3: mm | T3: mm | U3: mm | V3: mm | W3: mm | X3: mm | Y3: mm | Z3: mm | AA3: mm^4 | AB3: mm^6 | AC3: m | AE3: lb/ft
A4: Short Legs Back-to-Back
A5: * | B5: 2L203x152x25 | C5: * | D5: 11 | E5: 3 | F5: 152 | G5: 203 | H5: 25.4 | I5: 32.4 | J5: 7.99 | K5: 5.98 | L5: 40 | M5: 0.541 | N5: 131 | O5: 16700 | P5: 32 | Q5: 291 | R5: 43.7 | S5: 41.9 | T5: 92.4 | U5: 95.4 | V5: 96.1 | W5: 96.9 | X5: 98.4 | Y5: 100 | Z5: 29.2 | AA5: 3600 | AB5: 8.73 | AC5: 1.42 | AD5: 2L8x6x1.000 | AE5: 88.3
B6: 2L203x152x22 | C6: * | D6: 11 | E6: 3 | F6: 152 | G6: 203 | H6: 22.2 | I6: 32.5 | J6: 9.14 | K6: 6.85 | L6: 36 | M6: 0.545 | N6: 116 | O6: 14800 | P6: 28.8 | Q6: 259 | R6: 44.1 | S6: 40.7 | T6: 91.9 | U6: 94.8 | V6: 95.6 | W6: 96.3 | X6: 97.8 | Y6: 99.3 | Z6: 29.6 | AA6: 2430 | AB6: 6 | AC6: 1.42 | AD6: 2L8x6x0.875 | AE6: 77.9
B7: 2L203x152x19 | C7: * | D7: 11 | E7: 2 | F7: 152 | G7: 203 | H7: 19.1 | I7: 32.6 | J7: 10.6 | K7: 7.96 | L7: 34 | M7: 0.549 | N7: 101 | O7: 12800 | P7: 25.4 | Q7: 226 | R7: 44.5 | S7: 39.6 | T7: 91.4 | U7: 94.3 | V7: 95 | W7: 95.7 | X7: 97.2 | Y7: 98.8 | Z7: 30.1 | AA7: 1560 | AB7: 3.92 | AC7: 1.42 | AD7: 2L8x6x0.750 | AE7: 67.7
B8: 2L203x152x16 | C8: * | D8: 11 | E8: 2 | F8: 152 | G8: 203 | H8: 15.9 | I8: 32.8 | J8: 12.8 | K8: 9.56 | L8: 30 | M8: 0.553 | N8: 84.6 | O8: 10800 | P8: 21.8 | Q8: 192 | R8: 44.9 | S8: 38.5 | T8: 90.9 | U8: 93.7 | V8: 94.5 | W8: 95.2 | X8: 96.7 | Y8: 98.2 | Z8: 30.5 | AA8: 909 | AB8: 2.32 | AC8: 1.42 | AD8: 2L8x6x0.625 | AE8: 56.9
B9: 2L203x152x14 | C9: * | D9: 11 | E9: 2 | F9: 152 | G9: 203 | H9: 14.3 | I9: 32.9 | J9: 14.2 | K9: 10.6 | L9: 28 | M9: 0.554 | N9: 76.5 | O9: 9740 | P9: 19.9 | Q9: 174 | R9: 45.2 | S9: 37.9 | T9: 90.6 | U9: 93.5 | V9: 94.2 | W9: 94.9 | X9: 96.4 | Y9: 97.9 | Z9: 30.7 | AA9: 664 | AB9: 1.71 | AC9: 1.42 | AD9: 2L8x6x0.563 | AE9: 51.4
B10: 2L203x152x13 | C10: * | D10: 11 | E10: 1 | F10: 152 | G10: 203 | H10: 12.7 | I10: 33 | J10: 16 | K10: 12 | L10: 26 | M10: 0.556 | N10: 68.3 | O10: 8690 | P10: 17.9 | Q10: 156 | R10: 45.4 | S10: 37.3 | T10: 90.4 | U10: 93.2 | V10: 93.9 | W10: 94.6 | X10: 96.1 | Y10: 97.6 | Z10: 30.9 | AA10: 467 | AB10: 1.22 | AC10: 1.42 | AD10: 2L8x6x0.500 | AE10: 45.9
A11: * | B11: 2L203x102x25 | C11: * | D11: 11 | E11: 3 | F11: 102 | G11: 203 | H11: 25.4 | I11: 21.6 | J11: 7.99 | K11: 4.02 | L11: 40 | M11: 0.249 | N11: 111 | O11: 14200 | P11: 9.81 | Q11: 130 | R11: 26.3 | S11: 26.7 | T11: 100 | U11: 103 | V11: 104 | W11: 105 | X11: 106 | Y11: 108 | Z11: 14 | AA11: 3050 | AB11: 6.92 | AC11: 1.22 | AD11: 2L8x4x1.000 | AE11: 74.9
B12: 2L203x102x19 | C12: * | D12: 11 | E12: 2 | F12: 102 | G12: 203 | H12: 19.1 | I12: 21.7 | J12: 10.6 | K12: 5.34 | L12: 34 | M12: 0.26 | N12: 85.7 | O12: 10900 | P12: 7.9 | Q12: 102 | R12: 26.9 | S12: 24.3 | T12: 98.9 | U12: 102 | V12: 103 | W12: 104 | X12: 105 | Y12: 107 | Z12: 14.8 | AA12: 1330 | AB12: 3.11 | AC12: 1.22 | AD12: 2L8x4x0.750 | AE12: 57.6
B13: 2L203x102x13 | C13: * | D13: 11 | E13: 1 | F13: 102 | G13: 203 | H13: 12.7 | I13: 22.1 | J13: 16 | K13: 8.03 | L13: 26 | M13: 0.269 | N13: 58.3 | O13: 7420 | P13: 5.67 | Q13: 70.9 | R13: 27.6 | S13: 21.9 | T13: 97.8 | U13: 101 | V13: 102 | W13: 102 | X13: 104 | Y13: 105 | Z13: 15.6 | AA13: 399 | AB13: 0.965 | AC13: 1.22 | AD13: 2L8x4x0.500 | AE13: 39.2
A14: * | B14: 2L178x102x19 | C14: * | D14: 11 | E14: 2 | F14: 102 | G14: 178 | H14: 19.1 | I14: 21.9 | J14: 9.32 | K14: 5.34 | L14: 34 | M14: 0.325 | N14: 78.2 | O14: 9970 | P14: 7.64 | Q14: 100 | R14: 27.7 | S14: 25.8 | T14: 85.1 | U14: 88.1 | V14: 88.9 | W14: 89.7 | X14: 91.3 | Y14: 92.8 | Z14: 16.2 | AA14: 1210 | AB14: 2.16 | AC14: 1.12 | AD14: 2L7x4x0.750 | AE14: 52.6
B15: 2L178x102x16 | C15: * | D15: 11 | E15: 2 | F15: 102 | G15: 178 | H15: 15.9 | I15: 22.1 | J15: 11.2 | K15: 6.42 | L15: 30 | M15: 0.331 | N15: 65.9 | O15: 8400 | P15: 6.61 | Q15: 85.4 | R15: 28.1 | S15: 24.6 | T15: 84.5 | U15: 87.5 | V15: 88.3 | W15: 89.1 | X15: 90.6 | Y15: 92.2 | Z15: 16.6 | AA15: 708 | AB15: 1.28 | AC15: 1.12 | AD15: 2L7x4x0.625 | AE15: 44.3
B16: 2L178x102x13 | D16: 11 | E16: 1 | F16: 102 | G16: 178 | H16: 12.7 | I16: 22.2 | J16: 14 | K16: 8.03 | L16: 26 | M16: 0.336 | N16: 53.3 | O16: 6790 | P16: 5.5 | Q16: 69.9 | R16: 28.5 | S16: 23.4 | T16: 84 | U16: 86.9 | V16: 87.7 | W16: 88.5 | X16: 90 | Y16: 91.5 | Z16: 17 | AA16: 365 | AB16: 0.675 | AC16: 1.12 | AD16: 2L7x4x0.500 | AE16: 35.8
B17: 2L178x102x11 | C17: * | D17: 11 | E17: 1 | F17: 102 | G17: 178 | H17: 11.1 | I17: 22.3 | J17: 16 | K17: 9.19 | L17: 26 | M17: 0.339 | N17: 46.9 | O17: 5970 | P17: 4.9 | Q17: 61.9 | R17: 28.7 | S17: 22.8 | T17: 83.7 | U17: 86.6 | V17: 87.4 | W17: 88.2 | X17: 89.7 | Y17: 91.2 | Z17: 17.2 | AA17: 245 | AB17: 0.458 | AC17: 1.12 | AD17: 2L7x4x0.438 | AE17: 31.5
B18: 2L178x102x9.5 | D18: 11 | E18: 1 | F18: 102 | G18: 178 | H18: 9.53 | I18: 22.4 | J18: 18.7 | K18: 10.7 | L18: 24 | M18: 0.341 | N18: 40.5 | O18: 5160 | P18: 4.3 | Q18: 53.9 | R18: 28.9 | S18: 22.2 | T18: 83.4 | U18: 86.4 | V18: 87.1 | W18: 87.9 | X18: 89.4 | Y18: 90.9 | Z18: 17.4 | AA18: 156 | AB18: 0.294 | AC18: 1.12 | AD18: 2L7x4x0.375 | AE18: 27.2
A19: * | B19: 2L152x102x22 | C19: * | D19: 11 | E19: 3 | F19: 102 | G19: 152 | H19: 22.2 | I19: 21.9 | J19: 6.85 | K19: 4.59 | L19: 36 | M19: 0.427 | N19: 80.8 | O19: 10300 | P19: 8.2 | Q19: 112 | R19: 28.2 | S19: 28.7 | T19: 71.5 | U19: 74.5 | V19: 75.3 | W19: 76.1 | X19: 77.6 | Y19: 79.2 | Z19: 17.6 | AA19: 1690 | AB19: 2.16 | AC19: 1.02 | AD19: 2L6x4x0.875 | AE19: 54.3
B20: 2L152x102x19 | D20: 11 | E20: 2 | F20: 102 | G20: 152 | H20: 19.1 | I20: 21.9 | J20: 7.96 | K20: 5.34 | L20: 34 | M20: 0.434 | N20: 70.4 | O20: 8970 | P20: 7.32 | Q20: 98.3 | R20: 28.6 | S20: 27.5 | T20: 70.9 | U20: 73.9 | V20: 74.7 | W20: 75.5 | X20: 77 | Y20: 78.6 | Z20: 18 | AA20: 1090 | AB20: 1.42 | AC20: 1.02 | AD20: 2L6x4x0.750 | AE20: 47.3
B21: 2L152x102x16 | D21: 11 | E21: 2 | F21: 102 | G21: 152 | H21: 15.9 | I21: 22 | J21: 9.56 | K21: 6.42 | L21: 30 | M21: 0.44 | N21: 59.4 | O21: 7570 | P21: 6.34 | Q21: 83.8 | R21: 28.9 | S21: 26.4 | T21: 70.3 | U21: 73.3 | V21: 74.1 | W21: 74.8 | X21: 76.4 | Y21: 77.9 | Z21: 18.4 | AA21: 638 | AB21: 0.853 | AC21: 1.02 | AD21: 2L6x4x0.625 | AE21: 39.9
B22: 2L152x102x14 | C22: * | D22: 11 | E22: 2 | F22: 102 | G22: 152 | H22: 14.3 | I22: 22.1 | J22: 10.6 | K22: 7.13 | L22: 28 | M22: 0.443 | N22: 53.8 | O22: 6860 | P22: 5.82 | Q22: 76.4 | R22: 29.1 | S22: 25.8 | T22: 70.1 | U22: 73 | V22: 73.8 | W22: 74.5 | X22: 76.1 | Y22: 77.6 | Z22: 18.7 | AA22: 467 | AB22: 0.632 | AC22: 1.02 | AD22: 2L6x4x0.563 | AE22: 36.2
B23: 2L152x102x13 | D23: 11 | E23: 1 | F23: 102 | G23: 152 | H23: 12.7 | I23: 22.2 | J23: 12 | K23: 8.03 | L23: 26 | M23: 0.446 | N23: 48.1 | O23: 6130 | P23: 5.28 | Q23: 68.7 | R23: 29.3 | S23: 25.2 | T23: 69.8 | U23: 72.7 | V23: 73.5 | W23: 74.2 | X23: 75.8 | Y23: 77.3 | Z23: 18.9 | AA23: 330 | AB23: 0.451 | AC23: 1.02 | AD23: 2L6x4x0.500 | AE23: 32.3
B24: 2L152x102x11 | C24: * | D24: 11 | E24: 1 | F24: 102 | G24: 152 | H24: 11.1 | I24: 22.3 | J24: 13.7 | K24: 9.19 | L24: 26 | M24: 0.449 | N24: 42.3 | O24: 5390 | P24: 4.71 | Q24: 60.9 | R24: 29.6 | S24: 24.6 | T24: 69.5 | U24: 72.4 | V24: 73.2 | W24: 73.9 | X24: 75.5 | Y24: 77 | Z24: 19.1 | AA24: 221 | AB24: 0.307 | AC24: 1.02 | AD24: 2L6x4x0.438 | AE24: 28.4
B25: 2L152x102x9.5 | D25: 11 | E25: 1 | F25: 102 | G25: 152 | H25: 9.53 | I25: 22.4 | J25: 15.9 | K25: 10.7 | L25: 24 | M25: 0.451 | N25: 36.6 | O25: 4660 | P25: 4.13 | Q25: 53 | R25: 29.8 | S25: 24.1 | T25: 69.3 | U25: 72.2 | V25: 72.9 | W25: 73.7 | X25: 75.2 | Y25: 76.7 | Z25: 19.3 | AA25: 141 | AB25: 0.198 | AC25: 1.02 | AD25: 2L6x4x0.375 | AE25: 24.6
B26: 2L152x102x7.9 | D26: 11 | E26: 1 | F26: 102 | G26: 152 | H26: 7.94 | I26: 22.5 | J26: 19.1 | K26: 12.8 | L26: 22 | M26: 0.454 | N26: 30.7 | O26: 3910 | P26: 3.51 | Q26: 44.7 | R26: 30 | S26: 23.5 | T26: 69 | U26: 71.9 | V26: 72.6 | W26: 73.4 | X26: 74.9 | Y26: 76.4 | Z26: 19.5 | AA26: 82.1 | AB26: 0.116 | AC26: 1.02 | AD26: 2L6x4x0.313 | AE26: 20.6
A27: * | B27: 2L152x89x16 | D27: 11 | E27: 2 | F27: 88.9 | G27: 152 | H27: 15.9 | I27: 19.1 | J27: 9.56 | K27: 5.59 | L27: 30 | M27: 0.339 | N27: 56.2 | O27: 7160 | P27: 4.23 | Q27: 63.6 | R27: 24.3 | S27: 22.4 | T27: 72.3 | U27: 75.3 | V27: 76.1 | W27: 76.9 | X27: 78.5 | Y27: 80.1 | Z27: 14.4 | AA27: 603 | AB27: 0.786 | AC27: 0.964 | AD27: 2L6x3.5x0.625 | AE27: 37.7
B28: 2L152x89x13 | D28: 11 | E28: 1 | F28: 88.9 | G28: 152 | H28: 12.7 | I28: 19.3 | J28: 12 | K28: 7 | L28: 26 | M28: 0.345 | N28: 45.5 | O28: 5800 | P28: 3.54 | Q28: 52.2 | R28: 24.7 | S28: 21.2 | T28: 71.7 | U28: 74.7 | V28: 75.5 | W28: 76.3 | X28: 77.8 | Y28: 79.4 | Z28: 14.8 | AA28: 312 | AB28: 0.416 | AC28: 0.964 | AD28: 2L6x3.5x0.500 | AE28: 30.6
B29: 2L152x89x9.5 | D29: 11 | E29: 1 | F29: 88.9 | G29: 152 | H29: 9.53 | I29: 19.5 | J29: 15.9 | K29: 9.33 | L29: 24 | M29: 0.351 | N29: 34.6 | O29: 4410 | P29: 2.78 | Q29: 40.4 | R29: 25.1 | S29: 20 | T29: 71.2 | U29: 74.2 | V29: 74.9 | W29: 75.7 | X29: 77.2 | Y29: 78.7 | Z29: 15.2 | AA29: 134 | AB29: 0.182 | AC29: 0.964 | AD29: 2L6x3.5x0.375 | AE29: 23.3
B30: 2L152x89x7.9 | D30: 11 | E30: 1 | F30: 88.9 | G30: 152 | H30: 7.94 | I30: 19.6 | J30: 19.1 | K30: 11.2 | L30: 22 | M30: 0.354 | N30: 29 | O30: 3700 | P30: 2.37 | Q30: 34.1 | R30: 25.3 | S30: 19.4 | T30: 70.9 | U30: 73.9 | V30: 74.6 | W30: 75.4 | X30: 76.9 | Y30: 78.4 | Z30: 15.4 | AA30: 77.7 | AB30: 0.107 | AC30: 0.964 | AD30: 2L6x3.5x0.313 | AE30: 19.5
A31: * | B31: 2L127x89x19 | C31: * | D31: 11 | E31: 2 | F31: 88.9 | G31: 127 | H31: 19.1 | I31: 19 | J31: 6.65 | K31: 4.65 | L31: 32 | M31: 0.464 | N31: 59 | O31: 7520 | P31: 4.63 | Q31: 72.8 | R31: 24.8 | S31: 25.3 | T31: 59.3 | U31: 62.3 | V31: 63.1 | W31: 63.9 | X31: 65.5 | Y31: 67.1 | Z31: 15.8 | AA31: 914 | AB31: 0.821 | AC31: 0.864 | AD31: 2L5x3.5x0.750 | AE31: 39.7
B32: 2L127x89x16 | C32: * | D32: 11 | E32: 2 | F32: 88.9 | G32: 127 | H32: 15.9 | I32: 19.1 | J32: 7.99 | K32: 5.59 | L32: 28 | M32: 0.472 | N32: 49.9 | O32: 6360 | P32: 4.03 | Q32: 62.2 | R32: 25.2 | S32: 24.2 | T32: 58.7 | U32: 61.7 | V32: 62.5 | W32: 63.2 | X32: 64.8 | Y32: 66.4 | Z32: 16.2 | AA32: 536 | AB32: 0.495 | AC32: 0.864 | AD32: 2L5x3.5x0.625 | AE32: 33.6
B33: 2L127x89x13 | D33: 11 | E33: 1 | F33: 88.9 | G33: 127 | H33: 12.7 | I33: 19.2 | J33: 10 | K33: 7 | L33: 24 | M33: 0.479 | N33: 40.5 | O33: 5160 | P33: 3.37 | Q33: 51.2 | R33: 25.6 | S33: 23 | T33: 58.1 | U33: 61.1 | V33: 61.9 | W33: 62.6 | X33: 64.2 | Y33: 65.7 | Z33: 16.7 | AA33: 277 | AB33: 0.264 | AC33: 0.864 | AD33: 2L5x3.5x0.500 | AE33: 27.2
B34: 2L127x89x9.5 | D34: 11 | E34: 1 | F34: 88.9 | G34: 127 | H34: 9.53 | I34: 19.3 | J34: 13.3 | K34: 9.33 | L34: 22 | M34: 0.486 | N34: 30.9 | O34: 3930 | P34: 2.65 | Q34: 39.6 | R34: 26 | S34: 21.9 | T34: 57.6 | U34: 60.5 | V34: 61.3 | W34: 62 | X34: 63.6 | Y34: 65.1 | Z34: 17.1 | AA34: 119 | AB34: 0.116 | AC34: 0.864 | AD34: 2L5x3.5x0.375 | AE34: 20.7
B35: 2L127x89x7.9 | D35: 11 | E35: 1 | F35: 88.9 | G35: 127 | H35: 7.94 | I35: 19.4 | J35: 16 | K35: 11.2 | L35: 20 | M35: 0.489 | N35: 25.9 | O35: 3300 | P35: 2.26 | Q35: 33.5 | R35: 26.2 | S35: 21.3 | T35: 57.4 | U35: 60.3 | V35: 61 | W35: 61.7 | X35: 63.3 | Y35: 64.8 | Z35: 17.3 | AA35: 69.4 | AB35: 0.0688 | AC35: 0.864 | AD35: 2L5x3.5x0.313 | AE35: 17.4
B36: 2L127x89x6.4 | D36: 11 | E36: 1 | F36: 88.9 | G36: 127 | H36: 6.35 | I36: 19.6 | J36: 20 | K36: 14 | L36: 18 | M36: 0.492 | N36: 20.9 | O36: 2660 | P36: 1.86 | Q36: 27.2 | R36: 26.4 | S36: 20.7 | T36: 57.1 | U36: 60 | V36: 60.7 | W36: 61.5 | X36: 63 | Y36: 64.5 | Z36: 17.5 | AA36: 35.8 | AB36: 0.036 | AC36: 0.864 | AD36: 2L5x3.5x0.250 | AE36: 14
A37: * | B37: 2L127x76x13 | D37: 11 | E37: 1 | F37: 76.2 | G37: 127 | H37: 12.7 | I37: 16.5 | J37: 10 | K37: 6 | L37: 24 | M37: 0.357 | N37: 38 | O37: 4840 | P37: 2.15 | Q37: 37.6 | R37: 21.1 | S37: 19.1 | T37: 60 | U37: 63 | V37: 63.8 | W37: 64.6 | X37: 66.2 | Y37: 67.8 | Z37: 12.7 | AA37: 260 | AB37: 0.239 | AC37: 0.813 | AD37: 2L5x3x0.500 | AE37: 25.5
B38: 2L127x76x11 | C38: * | D38: 11 | E38: 1 | F38: 76.2 | G38: 127 | H38: 11.1 | I38: 16.5 | J38: 11.4 | K38: 6.86 | L38: 24 | M38: 0.361 | N38: 33.5 | O38: 4260 | P38: 1.93 | Q38: 33.4 | R38: 21.3 | S38: 18.5 | T38: 59.7 | U38: 62.7 | V38: 63.5 | W38: 64.3 | X38: 65.8 | Y38: 67.4 | Z38: 12.9 | AA38: 175 | AB38: 0.163 | AC38: 0.813 | AD38: 2L5x3x0.438 | AE38: 22.5
B39: 2L127x76x9.5 | D39: 11 | E39: 1 | F39: 76.2 | G39: 127 | H39: 9.53 | I39: 16.6 | J39: 13.3 | K39: 8 | L39: 22 | M39: 0.364 | N39: 29 | O39: 3690 | P39: 1.7 | Q39: 29.1 | R39: 21.5 | S39: 17.9 | T39: 59.5 | U39: 62.4 | V39: 63.2 | W39: 64 | X39: 65.5 | Y39: 67.1 | Z39: 13.1 | AA39: 112 | AB39: 0.105 | AC39: 0.813 | AD39: 2L5x3x0.375 | AE39: 19.5
B40: 2L127x76x7.9 | D40: 11 | E40: 1 | F40: 76.2 | G40: 127 | H40: 7.94 | I40: 16.7 | J40: 16 | K40: 9.6 | L40: 20 | M40: 0.368 | N40: 24.3 | O40: 3100 | P40: 1.45 | Q40: 24.7 | R40: 21.7 | S40: 17.3 | T40: 59.2 | U40: 62.1 | V40: 62.9 | W40: 63.7 | X40: 65.2 | Y40: 66.8 | Z40: 13.3 | AA40: 65.2 | AB40: 0.0623 | AC40: 0.813 | AD40: 2L5x3x0.313 | AE40: 16.4
...
